[2024-10-09T01:20:39.857+0000] {local_task_job_runner.py:120} INFO - ::group::Pre task execution logs
[2024-10-09T01:20:39.868+0000] {taskinstance.py:2076} INFO - Dependencies all met for dep_context=non-requeueable deps ti=<TaskInstance: Nikita_Lapshin_experiment.get_data scheduled__2024-10-08T01:00:00+00:00 [queued]>
[2024-10-09T01:20:39.874+0000] {taskinstance.py:2076} INFO - Dependencies all met for dep_context=requeueable deps ti=<TaskInstance: Nikita_Lapshin_experiment.get_data scheduled__2024-10-08T01:00:00+00:00 [queued]>
[2024-10-09T01:20:39.874+0000] {taskinstance.py:2306} INFO - Starting attempt 1 of 4
[2024-10-09T01:20:39.884+0000] {taskinstance.py:2330} INFO - Executing <Task(PythonOperator): get_data> on 2024-10-08 01:00:00+00:00
[2024-10-09T01:20:39.891+0000] {standard_task_runner.py:64} INFO - Started process 1532 to run task
[2024-10-09T01:20:39.895+0000] {standard_task_runner.py:90} INFO - Running: ['***', 'tasks', 'run', 'Nikita_Lapshin_experiment', 'get_data', 'scheduled__2024-10-08T01:00:00+00:00', '--job-id', '11', '--raw', '--subdir', 'DAGS_FOLDER/HW2.py', '--cfg-path', '/tmp/tmppxek5jit']
[2024-10-09T01:20:39.899+0000] {standard_task_runner.py:91} INFO - Job 11: Subtask get_data
[2024-10-09T01:20:39.951+0000] {task_command.py:426} INFO - Running <TaskInstance: Nikita_Lapshin_experiment.get_data scheduled__2024-10-08T01:00:00+00:00 [running]> on host 8027b3e99bd6
[2024-10-09T01:20:40.041+0000] {taskinstance.py:2648} INFO - Exporting env vars: AIRFLOW_CTX_DAG_OWNER='Lapshin Nikita' AIRFLOW_CTX_DAG_ID='Nikita_Lapshin_experiment' AIRFLOW_CTX_TASK_ID='get_data' AIRFLOW_CTX_EXECUTION_DATE='2024-10-08T01:00:00+00:00' AIRFLOW_CTX_TRY_NUMBER='1' AIRFLOW_CTX_DAG_RUN_ID='scheduled__2024-10-08T01:00:00+00:00'
[2024-10-09T01:20:40.043+0000] {taskinstance.py:430} INFO - ::endgroup::
[2024-10-09T01:20:40.282+0000] {base.py:84} INFO - Using connection ID 's3_connection' for task execution.
[2024-10-09T01:20:40.284+0000] {connection_wrapper.py:388} INFO - AWS Connection (conn_id='s3_connection', conn_type='aws') credentials retrieved from login and password.
[2024-10-09T01:20:41.659+0000] {taskinstance.py:441} INFO - ::group::Post task execution logs
[2024-10-09T01:20:41.660+0000] {taskinstance.py:2905} ERROR - Task failed with exception
Traceback (most recent call last):
  File "/home/airflow/.local/lib/python3.10/site-packages/airflow/models/taskinstance.py", line 465, in _execute_task
    result = _execute_callable(context=context, **execute_callable_kwargs)
  File "/home/airflow/.local/lib/python3.10/site-packages/airflow/models/taskinstance.py", line 432, in _execute_callable
    return execute_callable(context=context, **execute_callable_kwargs)
  File "/home/airflow/.local/lib/python3.10/site-packages/airflow/models/baseoperator.py", line 401, in wrapper
    return func(self, *args, **kwargs)
  File "/home/airflow/.local/lib/python3.10/site-packages/airflow/operators/python.py", line 235, in execute
    return_value = self.execute_callable()
  File "/home/airflow/.local/lib/python3.10/site-packages/airflow/operators/python.py", line 252, in execute_callable
    return self.python_callable(*self.op_args, **self.op_kwargs)
  File "/opt/airflow/dags/HW2.py", line 55, in get_data
    s3_hook.load_string(data.data.to_csv(), path, bucket_name=BUCKET, replace=True)
  File "/home/airflow/.local/lib/python3.10/site-packages/airflow/providers/amazon/aws/hooks/s3.py", line 158, in wrapper
    return func(*bound_args.args, **bound_args.kwargs)
  File "/home/airflow/.local/lib/python3.10/site-packages/airflow/providers/amazon/aws/hooks/s3.py", line 132, in wrapper
    return func(*bound_args.args, **bound_args.kwargs)
  File "/home/airflow/.local/lib/python3.10/site-packages/airflow/providers/amazon/aws/hooks/s3.py", line 1172, in load_string
    self._upload_file_obj(f, key, bucket_name, replace, encrypt, acl_policy)
  File "/home/airflow/.local/lib/python3.10/site-packages/airflow/providers/amazon/aws/hooks/s3.py", line 1255, in _upload_file_obj
    client.upload_fileobj(
  File "/home/airflow/.local/lib/python3.10/site-packages/boto3/s3/inject.py", line 642, in upload_fileobj
    return future.result()
  File "/home/airflow/.local/lib/python3.10/site-packages/s3transfer/futures.py", line 103, in result
    return self._coordinator.result()
  File "/home/airflow/.local/lib/python3.10/site-packages/s3transfer/futures.py", line 266, in result
    raise self._exception
  File "/home/airflow/.local/lib/python3.10/site-packages/s3transfer/tasks.py", line 139, in __call__
    return self._execute_main(kwargs)
  File "/home/airflow/.local/lib/python3.10/site-packages/s3transfer/tasks.py", line 162, in _execute_main
    return_value = self._main(**kwargs)
  File "/home/airflow/.local/lib/python3.10/site-packages/s3transfer/upload.py", line 764, in _main
    client.put_object(Bucket=bucket, Key=key, Body=body, **extra_args)
  File "/home/airflow/.local/lib/python3.10/site-packages/botocore/client.py", line 565, in _api_call
    return self._make_api_call(operation_name, kwargs)
  File "/home/airflow/.local/lib/python3.10/site-packages/botocore/client.py", line 1021, in _make_api_call
    raise error_class(parsed_response, operation_name)
botocore.exceptions.ClientError: An error occurred (SignatureDoesNotMatch) when calling the PutObject operation: The request signature we calculated does not match the signature you provided. Check your key and signing method.
[2024-10-09T01:20:41.684+0000] {taskinstance.py:1206} INFO - Marking task as UP_FOR_RETRY. dag_id=Nikita_Lapshin_experiment, task_id=get_data, run_id=scheduled__2024-10-08T01:00:00+00:00, execution_date=20241008T010000, start_date=20241009T012039, end_date=20241009T012041
[2024-10-09T01:20:41.701+0000] {standard_task_runner.py:110} ERROR - Failed to execute job 11 for task get_data (An error occurred (SignatureDoesNotMatch) when calling the PutObject operation: The request signature we calculated does not match the signature you provided. Check your key and signing method.; 1532)
[2024-10-09T01:20:41.739+0000] {local_task_job_runner.py:243} INFO - Task exited with return code 1
[2024-10-09T01:20:41.770+0000] {taskinstance.py:3503} INFO - 0 downstream tasks scheduled from follow-on schedule check
[2024-10-09T01:20:41.771+0000] {local_task_job_runner.py:222} INFO - ::endgroup::
