[2024-10-12T18:11:26.057+0000] {local_task_job_runner.py:120} INFO - ::group::Pre task execution logs
[2024-10-12T18:11:26.105+0000] {taskinstance.py:2076} INFO - Dependencies all met for dep_context=non-requeueable deps ti=<TaskInstance: Nikita_Lapshin_experiment.train_and_log_model manual__2024-10-12T18:09:38.413021+00:00 [queued]>
[2024-10-12T18:11:26.127+0000] {taskinstance.py:2076} INFO - Dependencies all met for dep_context=requeueable deps ti=<TaskInstance: Nikita_Lapshin_experiment.train_and_log_model manual__2024-10-12T18:09:38.413021+00:00 [queued]>
[2024-10-12T18:11:26.128+0000] {taskinstance.py:2306} INFO - Starting attempt 2 of 4
[2024-10-12T18:11:26.152+0000] {taskinstance.py:2330} INFO - Executing <Task(PythonOperator): train_and_log_model> on 2024-10-12 18:09:38.413021+00:00
[2024-10-12T18:11:26.201+0000] {standard_task_runner.py:64} INFO - Started process 305 to run task
[2024-10-12T18:11:26.212+0000] {standard_task_runner.py:90} INFO - Running: ['***', 'tasks', 'run', 'Nikita_Lapshin_experiment', 'train_and_log_model', 'manual__2024-10-12T18:09:38.413021+00:00', '--job-id', '89', '--raw', '--subdir', 'DAGS_FOLDER/HW2.py', '--cfg-path', '/tmp/tmpk3__f39v']
[2024-10-12T18:11:26.221+0000] {standard_task_runner.py:91} INFO - Job 89: Subtask train_and_log_model
[2024-10-12T18:11:26.366+0000] {task_command.py:426} INFO - Running <TaskInstance: Nikita_Lapshin_experiment.train_and_log_model manual__2024-10-12T18:09:38.413021+00:00 [running]> on host 8027b3e99bd6
[2024-10-12T18:11:26.575+0000] {taskinstance.py:2648} INFO - Exporting env vars: AIRFLOW_CTX_DAG_OWNER='Lapshin Nikita' AIRFLOW_CTX_DAG_ID='Nikita_Lapshin_experiment' AIRFLOW_CTX_TASK_ID='train_and_log_model' AIRFLOW_CTX_EXECUTION_DATE='2024-10-12T18:09:38.413021+00:00' AIRFLOW_CTX_TRY_NUMBER='2' AIRFLOW_CTX_DAG_RUN_ID='manual__2024-10-12T18:09:38.413021+00:00'
[2024-10-12T18:11:26.579+0000] {taskinstance.py:430} INFO - ::endgroup::
[2024-10-12T18:11:26.621+0000] {s3.py:1422} INFO - Downloading source S3 file from Bucket mlops-2 with path datasets/prepared_data.csv
[2024-10-12T18:11:26.639+0000] {base.py:84} INFO - Using connection ID 's3_connection' for task execution.
[2024-10-12T18:11:26.642+0000] {connection_wrapper.py:388} INFO - AWS Connection (conn_id='s3_connection', conn_type='aws') credentials retrieved from login and password.
[2024-10-12T18:11:27.467+0000] {logging_mixin.py:188} INFO - result1
[2024-10-12T18:11:27.517+0000] {logging_mixin.py:188} WARNING - 2024/10/12 18:11:27 WARNING mlflow.utils.git_utils: Failed to import Git (the Git executable is probably not on your PATH), so Git SHA is not available. Error: Failed to initialize: Bad git executable.
The git executable must be specified in one of the following ways:
    - be included in your $PATH
    - be set via $GIT_PYTHON_GIT_EXECUTABLE
    - explicitly set via git.refresh(<full-path-to-git-executable>)

All git commands will error until this is rectified.

This initial message can be silenced or aggravated in the future by setting the
$GIT_PYTHON_REFRESH environment variable. Use one of the following values:
    - quiet|q|silence|s|silent|none|n|0: for no message or exception
    - warn|w|warning|log|l|1: for a warning message (logging level CRITICAL, displayed by default)
    - error|e|exception|raise|r|2: for a raised exception

Example:
    export GIT_PYTHON_REFRESH=quiet
[2024-10-12T18:11:44.076+0000] {logging_mixin.py:188} INFO - result2 random_forest
[2024-10-12T18:11:52.956+0000] {logging_mixin.py:188} WARNING - 2024/10/12 18:11:52 WARNING mlflow.models.model: Input example should be provided to infer model signature if the model signature is not provided when logging the model.
[2024-10-12T18:11:53.055+0000] {logging_mixin.py:188} WARNING - 2024/10/12 18:11:53 INFO mlflow.tracking._tracking_service.client: üèÉ View run random_forest_run at: http://mlflow-service:5000/#/experiments/603016174840441006/runs/5e59e6c83d0c496caae0908dba4fc445.
[2024-10-12T18:11:53.056+0000] {logging_mixin.py:188} WARNING - 2024/10/12 18:11:53 INFO mlflow.tracking._tracking_service.client: üß™ View experiment at: http://mlflow-service:5000/#/experiments/603016174840441006.
[2024-10-12T18:11:53.174+0000] {logging_mixin.py:188} WARNING - 2024/10/12 18:11:53 INFO mlflow.tracking._tracking_service.client: üèÉ View run @GodSiemens at: http://mlflow-service:5000/#/experiments/603016174840441006/runs/9e5c9a51c0dc4acca4ec5bd80d556b32.
[2024-10-12T18:11:53.178+0000] {logging_mixin.py:188} WARNING - 2024/10/12 18:11:53 INFO mlflow.tracking._tracking_service.client: üß™ View experiment at: http://mlflow-service:5000/#/experiments/603016174840441006.
[2024-10-12T18:11:53.198+0000] {taskinstance.py:441} INFO - ::group::Post task execution logs
[2024-10-12T18:11:53.202+0000] {taskinstance.py:2905} ERROR - Task failed with exception
Traceback (most recent call last):
  File "/home/airflow/.local/lib/python3.10/site-packages/airflow/models/taskinstance.py", line 465, in _execute_task
    result = _execute_callable(context=context, **execute_callable_kwargs)
  File "/home/airflow/.local/lib/python3.10/site-packages/airflow/models/taskinstance.py", line 432, in _execute_callable
    return execute_callable(context=context, **execute_callable_kwargs)
  File "/home/airflow/.local/lib/python3.10/site-packages/airflow/models/baseoperator.py", line 401, in wrapper
    return func(self, *args, **kwargs)
  File "/home/airflow/.local/lib/python3.10/site-packages/airflow/operators/python.py", line 235, in execute
    return_value = self.execute_callable()
  File "/home/airflow/.local/lib/python3.10/site-packages/airflow/operators/python.py", line 252, in execute_callable
    return self.python_callable(*self.op_args, **self.op_kwargs)
  File "/opt/airflow/dags/HW2.py", line 113, in train_and_log_model
    eval_results = mlflow.evaluate(
  File "/home/airflow/.local/lib/python3.10/site-packages/mlflow/models/evaluation/base.py", line 1531, in evaluate
    raise MlflowException(
mlflow.exceptions.MlflowException: The model argument must be a string URI referring to an MLflow model, an MLflow Deployments endpoint URI, an instance of `mlflow.pyfunc.PyFuncModel`, a function, or None.
[2024-10-12T18:11:53.247+0000] {taskinstance.py:1206} INFO - Marking task as UP_FOR_RETRY. dag_id=Nikita_Lapshin_experiment, task_id=train_and_log_model, run_id=manual__2024-10-12T18:09:38.413021+00:00, execution_date=20241012T180938, start_date=20241012T181126, end_date=20241012T181153
[2024-10-12T18:11:53.277+0000] {standard_task_runner.py:110} ERROR - Failed to execute job 89 for task train_and_log_model (The model argument must be a string URI referring to an MLflow model, an MLflow Deployments endpoint URI, an instance of `mlflow.pyfunc.PyFuncModel`, a function, or None.; 305)
[2024-10-12T18:11:53.325+0000] {local_task_job_runner.py:243} INFO - Task exited with return code 1
[2024-10-12T18:11:53.409+0000] {taskinstance.py:3503} INFO - 0 downstream tasks scheduled from follow-on schedule check
[2024-10-12T18:11:53.410+0000] {local_task_job_runner.py:222} INFO - ::endgroup::
